<?xml version="1.0" ?>
<robot name="shunk-6-dof-guide-arm">
  <link name="Base">
    <inertial>
      <mass value="8.01062e-1"/>
      <origin xyz="-1.67003e-1 3.43750e-6 2.32286e-1"/>
      <inertia ixx="5.43953e-4" ixy="-2.21300e-7" ixz="-2.60353e-8" iyy="5.44424e-4" iyz="-6.50883e-8" izz="7.61884e-4"/>
    </inertial>
    <visual>
      <origin rpy="0 0 0" xyz="0 0 0"/>
      <geometry>
        <mesh filename="meshes/Schunk/Base.STL"/>
      </geometry>
    </visual>
    <collision>
      <origin rpy="0 0 0" xyz="-0.075 0 -0.045"/>
      <geometry>
        <capsule radius="0.110" length="0.21"/>
      </geometry>
    </collision>
    <collision>
      <origin rpy="0 0 0" xyz="-0.075 0 0.105"/>
      <geometry>
        <capsule radius="0.075" length="0.09"/>
      </geometry>
    </collision>
    <collision>
      <origin rpy="0 0 0" xyz="-0.62 -0.37 -0.35"/>
      <geometry>
        <box size="1 1 1"/>
      </geometry>
    </collision>
  </link>
  <joint name="Joint_0" type="continuous">
    <origin rpy="0 0 1.5708" xyz="-0.167 0 0.304"/>
    <parent link="Base"/>
    <child link="Link_0"/>
    <axis xyz="0 0 1"/>
    <limit effort="0" lower="0" upper="0" velocity="0"/>
  </joint>
  <link name="Link_0">
    <inertial>
      <mass value="5.29678"/>
      <origin xyz="7.86719e-3, 1.62500e-6, -7.90200e-3"/>
      <inertia ixx="1.26812e-2" ixy="-4.37393e-7" ixz="-3.38423e-4" iyy="1.55385e-2" iyz="-3.80116e-7" izz="1.26371e-2"/>
    </inertial>
    <visual>
      <origin rpy="0 0 0" xyz="0 0 0"/>
      <geometry>
        <mesh filename="meshes/Schunk/Link_0.STL"/>
      </geometry>
    </visual>
    <collision>
      <origin rpy="0 0 0" xyz="0 0 0"/>
      <geometry>
        <mesh filename="meshes/Schunk/Link_0_collision.STL"/>
      </geometry>
    </collision>
  </link>
  <joint name="Joint_1" type="continuous">
    <origin rpy="0 -1.5708 3.14159" xyz="0 0 0"/>
    <parent link="Link_0"/>
    <child link="Link_1"/>
    <axis xyz="0 0 1"/>
    <limit effort="0" lower="0" upper="0" velocity="0"/>
  </joint>
  <link name="Link_1">
    <inertial>
      <mass value="6.52440"/>
      <origin xyz="1.74996e-1 -6.25000e-8  1.09032e-1"/>
      <inertia ixx="7.23697e-3" ixy="5.20706e-9" ixz="-2.60353e-9" iyy="1.17643e-1" iyz="0.00000" izz="1.18174e-1"/>
    </inertial>
    <visual>
      <origin rpy="0 0 0" xyz="0 0 0"/>
      <geometry>
        <mesh filename="meshes/Schunk/Link_1.STL"/>
      </geometry>
    </visual>
    <collision>
      <origin rpy="0 0 0" xyz="0 0 0"/>
      <geometry>
        <mesh filename="meshes/Schunk/Link_1_collision.STL"/>
      </geometry>
    </collision>
  </link>
  <joint name="Joint_2" type="continuous">
    <origin rpy="3.14159 0 0" xyz="0.350 0 0"/>
    <parent link="Link_1"/>
    <child link="Link_2"/>
    <axis xyz="0 0 1"/>
    <limit effort="0" lower="0" upper="0" velocity="0"/>
  </joint>
  <link name="Link_2">
    <inertial>
      <mass value="5.29678"/>
      <origin xyz="7.86638e-3 6.87500e-7 -7.90200e-3"/>
      <inertia ixx="1.26812e-2" ixy="-4.37393e-7" ixz="-3.38423e-4" iyy="1.55385e-2" iyz="-3.80116e-7" izz="1.26371e-2"/>
    </inertial>
    <visual>
      <origin rpy="0 0 0" xyz="0 0 0"/>
      <geometry>
        <mesh filename="meshes/Schunk/Link_2.STL"/>
      </geometry>
    </visual>
    <collision>
      <origin rpy="0 0 0" xyz="0 0 0"/>
      <geometry>
        <mesh filename="meshes/Schunk/Link_2_collision.STL"/>
      </geometry>
    </collision>
  </link>
  <joint name="Joint_3" type="continuous">
    <origin rpy="0 1.5708 0" xyz="0 0 0"/>
    <parent link="Link_2"/>
    <child link="Link_3"/>
    <axis xyz="0 0 1"/>
    <limit effort="0" lower="0" upper="0" velocity="0"/>
  </joint>
  <link name="Link_3">
    <inertial>
      <mass value="3.06309"/>
      <origin xyz="3.94769e-2 0.00000 1.67707e-1"/>
      <inertia ixx="2.28956e-2" ixy="0.00000" ixz="-7.43135e-3" iyy="2.59133e-2" iyz="0.00000" izz="5.78435e-3"/>
    </inertial>
    <visual>
      <origin rpy="0 0 0" xyz="0 0 0"/>
      <geometry>
        <mesh filename="meshes/Schunk/Link_3.STL"/>
      </geometry>
    </visual>
    <collision>
      <origin rpy="0 0 0" xyz="0 0 0"/>
      <geometry>
        <mesh filename="meshes/Schunk/Link_3_a_collision.STL"/>
      </geometry>
    </collision>
    <collision>
      <origin rpy="0 0 0" xyz="0 0 0"/>
      <geometry>
        <mesh filename="meshes/Schunk/Link_3_b_collision.STL"/>
      </geometry>
    </collision>
    <collision>
      <origin rpy="0 0 0" xyz="0.09 0 0.30172"/>
      <geometry>
        <sphere radius="0.045"/>
      </geometry>
    </collision>
  </link>
  <joint name="Joint_4" type="continuous">
    <origin rpy="0 -1.5708 0" xyz="0 0 0.305"/>
    <parent link="Link_3"/>
    <child link="Link_4"/>
    <axis xyz="0 0 1"/>
    <limit effort="0" lower="0" upper="0" velocity="0"/>
  </joint>
  <link name="Link_4">
    <inertial>
      <mass value="2.60643"/>
      <origin xyz="7.39962e-3 -1.37500e-6 -4.78887e-3"/>
      <inertia ixx="3.71973e-3" ixy="-3.12424e-8" ixz="-9.33184e-5" iyy="4.83394e-3" iyz=" 1.04141e-8" izz="4.13746e-3"/>
    </inertial>
    <visual>
      <origin rpy="0 0 0" xyz="0 0 0"/>
      <geometry>
        <mesh filename="meshes/Schunk/Link_4.STL"/>
      </geometry>
    </visual>
    <collision>
      <origin rpy="0 0 0" xyz="0 0 0"/>
      <geometry>
        <mesh filename="meshes/Schunk/Link_4_collision.STL"/>
      </geometry>
    </collision>
  </link>
  <joint name="Joint_5" type="continuous">
    <origin rpy="0 1.5708 0" xyz="0 0 0"/>
    <parent link="Link_4"/>
    <child link="End_Effector"/>
    <axis xyz="0 0 1"/>
    <limit effort="0" lower="0" upper="0" velocity="0"/>
  </joint>
  <link name="End_Effector">
    <inertial>
      <mass value="4.46596e-1"/>
      <origin xyz="2.00644e-3 3.35236e-2 1.22747e-1"/>
      <inertia ixx="1.88826e-3" ixy="-6.54528e-6" ixz="-1.62591e-5" iyy="6.68420e-4" iyz="-7.71822e-4" izz="1.40835e-3"/>
    </inertial>
    <visual>
      <origin rpy="0 0 0" xyz="0 0 0"/>
      <geometry>
        <mesh filename="meshes/Schunk/End_Effector_Straight.STL"/>
      </geometry>
    </visual>
    <collision>
      <origin rpy="0 0 0" xyz="0 0 0"/>
      <geometry>
        <mesh filename="meshes/Schunk/End_Effector_Straight_collision.STL"/>
      </geometry>
    </collision>
  </link>
  <joint name="Sensor_Flange" type="fixed">
    <origin rpy="0 0 1.5708" xyz="0 0 0.108675"/>
    <parent link="End_Effector"/>
    <child link="Weight"/>
    <axis xyz="0 0 0"/>
  </joint>
  <!--
    This link corresponds to the haptic proxy, which was previously the only physically simulated part of the arm.
    <origin> corresponds to the older v_sf_haptic, except it now also includes an orientation component with the X-axis along the handpiece handle.
  -->
  <link name="Weight">
    <inertial>
      <mass value="10.0"/>
      <origin xyz="1.17591e-1 -2.08302e-3 7.64603e-2" rpy="0 -0.38663 -0.03176"/>
      <inertia ixx="4.16667e-2" ixy="0.00000" ixz="0.00000" iyy="1.66667e-1" iyz="0.00000" izz="1.66667e-1"/>
    </inertial>
  </link>
</robot>
